telegram.vendor.ptb_urllib3.urllib3.connectionpool - WARNING - Retrying (Retry(total=2, connect=None, read=None, redirect=None)) after connection broken by 'ConnectTimeoutError(<telegram.vendor.ptb_urllib3.urllib3.connection.VerifiedHTTPSConnection object at 0x105b37f98>, 'Connection to api.telegram.org timed out. (connect timeout=5.0)')': /bot509144200:AAGoB1WgyWiasouuaO2jPhD7IG0pHRz2iyc/deleteWebhook
telegram.vendor.ptb_urllib3.urllib3.connectionpool - WARNING - Retrying (Retry(total=1, connect=None, read=None, redirect=None)) after connection broken by 'ConnectTimeoutError(<telegram.vendor.ptb_urllib3.urllib3.connection.VerifiedHTTPSConnection object at 0x105b470f0>, 'Connection to api.telegram.org timed out. (connect timeout=5.0)')': /bot509144200:AAGoB1WgyWiasouuaO2jPhD7IG0pHRz2iyc/deleteWebhook
telegram.vendor.ptb_urllib3.urllib3.connectionpool - WARNING - Retrying (Retry(total=0, connect=None, read=None, redirect=None)) after connection broken by 'ConnectTimeoutError(<telegram.vendor.ptb_urllib3.urllib3.connection.VerifiedHTTPSConnection object at 0x105b47588>, 'Connection to api.telegram.org timed out. (connect timeout=5.0)')': /bot509144200:AAGoB1WgyWiasouuaO2jPhD7IG0pHRz2iyc/deleteWebhook
telegram.ext.updater - ERROR - Error while bootstrap del webhook: urllib3 HTTPError HTTPSConnectionPool(host='api.telegram.org', port=443): Max retries exceeded with url: /bot509144200:AAGoB1WgyWiasouuaO2jPhD7IG0pHRz2iyc/deleteWebhook (Caused by ConnectTimeoutError(<telegram.vendor.ptb_urllib3.urllib3.connection.VerifiedHTTPSConnection object at 0x105b585c0>, 'Connection to api.telegram.org timed out. (connect timeout=5.0)'))
telegram.ext.updater - WARNING - Failed bootstrap phase; try=1 max_retries=-1
telegram.vendor.ptb_urllib3.urllib3.connectionpool - WARNING - Retrying (Retry(total=2, connect=None, read=None, redirect=None)) after connection broken by 'ConnectTimeoutError(<telegram.vendor.ptb_urllib3.urllib3.connection.VerifiedHTTPSConnection object at 0x105b588d0>, 'Connection to api.telegram.org timed out. (connect timeout=5.0)')': /bot509144200:AAGoB1WgyWiasouuaO2jPhD7IG0pHRz2iyc/deleteWebhook
telegram.vendor.ptb_urllib3.urllib3.connectionpool - WARNING - Retrying (Retry(total=1, connect=None, read=None, redirect=None)) after connection broken by 'ConnectTimeoutError(<telegram.vendor.ptb_urllib3.urllib3.connection.VerifiedHTTPSConnection object at 0x105b589e8>, 'Connection to api.telegram.org timed out. (connect timeout=5.0)')': /bot509144200:AAGoB1WgyWiasouuaO2jPhD7IG0pHRz2iyc/deleteWebhook
telegram.ext.updater - INFO - Received signal 2 (SIGINT), stopping...
telegram.ext.updater - WARNING - Exiting immediately!
telegram.vendor.ptb_urllib3.urllib3.connectionpool - WARNING - Retrying (Retry(total=2, connect=None, read=None, redirect=None)) after connection broken by 'ConnectTimeoutError(<telegram.vendor.ptb_urllib3.urllib3.connection.VerifiedHTTPSConnection object at 0x10f2a6f98>, 'Connection to api.telegram.org timed out. (connect timeout=5.0)')': /bot509144200:AAGoB1WgyWiasouuaO2jPhD7IG0pHRz2iyc/deleteWebhook
telegram.vendor.ptb_urllib3.urllib3.connectionpool - WARNING - Retrying (Retry(total=1, connect=None, read=None, redirect=None)) after connection broken by 'ConnectTimeoutError(<telegram.vendor.ptb_urllib3.urllib3.connection.VerifiedHTTPSConnection object at 0x10f2b60f0>, 'Connection to api.telegram.org timed out. (connect timeout=5.0)')': /bot509144200:AAGoB1WgyWiasouuaO2jPhD7IG0pHRz2iyc/deleteWebhook
telegram.vendor.ptb_urllib3.urllib3.connectionpool - WARNING - Retrying (Retry(total=0, connect=None, read=None, redirect=None)) after connection broken by 'ConnectTimeoutError(<telegram.vendor.ptb_urllib3.urllib3.connection.VerifiedHTTPSConnection object at 0x10f2b6518>, 'Connection to api.telegram.org timed out. (connect timeout=5.0)')': /bot509144200:AAGoB1WgyWiasouuaO2jPhD7IG0pHRz2iyc/deleteWebhook
telegram.ext.updater - ERROR - Error while bootstrap del webhook: urllib3 HTTPError HTTPSConnectionPool(host='api.telegram.org', port=443): Max retries exceeded with url: /bot509144200:AAGoB1WgyWiasouuaO2jPhD7IG0pHRz2iyc/deleteWebhook (Caused by ConnectTimeoutError(<telegram.vendor.ptb_urllib3.urllib3.connection.VerifiedHTTPSConnection object at 0x10f2c75c0>, 'Connection to api.telegram.org timed out. (connect timeout=5.0)'))
telegram.ext.updater - WARNING - Failed bootstrap phase; try=1 max_retries=-1
telegram.vendor.ptb_urllib3.urllib3.connectionpool - WARNING - Retrying (Retry(total=2, connect=None, read=None, redirect=None)) after connection broken by 'ConnectTimeoutError(<telegram.vendor.ptb_urllib3.urllib3.connection.VerifiedHTTPSConnection object at 0x10f2c78d0>, 'Connection to api.telegram.org timed out. (connect timeout=5.0)')': /bot509144200:AAGoB1WgyWiasouuaO2jPhD7IG0pHRz2iyc/deleteWebhook
telegram.vendor.ptb_urllib3.urllib3.connectionpool - WARNING - Retrying (Retry(total=1, connect=None, read=None, redirect=None)) after connection broken by 'ConnectTimeoutError(<telegram.vendor.ptb_urllib3.urllib3.connection.VerifiedHTTPSConnection object at 0x10f2c79e8>, 'Connection to api.telegram.org timed out. (connect timeout=5.0)')': /bot509144200:AAGoB1WgyWiasouuaO2jPhD7IG0pHRz2iyc/deleteWebhook
telegram.vendor.ptb_urllib3.urllib3.connectionpool - WARNING - Retrying (Retry(total=0, connect=None, read=None, redirect=None)) after connection broken by 'ConnectTimeoutError(<telegram.vendor.ptb_urllib3.urllib3.connection.VerifiedHTTPSConnection object at 0x10f2c7a90>, 'Connection to api.telegram.org timed out. (connect timeout=5.0)')': /bot509144200:AAGoB1WgyWiasouuaO2jPhD7IG0pHRz2iyc/deleteWebhook
telegram.ext.updater - ERROR - Error while bootstrap del webhook: urllib3 HTTPError HTTPSConnectionPool(host='api.telegram.org', port=443): Max retries exceeded with url: /bot509144200:AAGoB1WgyWiasouuaO2jPhD7IG0pHRz2iyc/deleteWebhook (Caused by ConnectTimeoutError(<telegram.vendor.ptb_urllib3.urllib3.connection.VerifiedHTTPSConnection object at 0x10f2c7ba8>, 'Connection to api.telegram.org timed out. (connect timeout=5.0)'))
telegram.ext.updater - WARNING - Failed bootstrap phase; try=2 max_retries=-1
telegram.vendor.ptb_urllib3.urllib3.connectionpool - WARNING - Retrying (Retry(total=2, connect=None, read=None, redirect=None)) after connection broken by 'ConnectTimeoutError(<telegram.vendor.ptb_urllib3.urllib3.connection.VerifiedHTTPSConnection object at 0x10f2c7940>, 'Connection to api.telegram.org timed out. (connect timeout=5.0)')': /bot509144200:AAGoB1WgyWiasouuaO2jPhD7IG0pHRz2iyc/deleteWebhook
telegram.ext.updater - INFO - Received signal 2 (SIGINT), stopping...
telegram.ext.updater - WARNING - Exiting immediately!
telegram.ext.updater - INFO - Received signal 2 (SIGINT), stopping...
telegram.ext.updater - WARNING - Exiting immediately!
telegram.ext.updater - INFO - Received signal 2 (SIGINT), stopping...
telegram.ext.updater - WARNING - Exiting immediately!
telegram.ext.dispatcher - WARNING - A TelegramError was raised while processing the Update
telegram.ext.dispatcher - ERROR - No error handlers are registered, logging exception...
Traceback (most recent call last):
  File "/Library/Frameworks/Python.framework/Versions/3.6/lib/python3.6/site-packages/telegram/vendor/ptb_urllib3/urllib3/connectionpool.py", line 617, in urlopen
    chunked=chunked)
  File "/Library/Frameworks/Python.framework/Versions/3.6/lib/python3.6/site-packages/telegram/vendor/ptb_urllib3/urllib3/connectionpool.py", line 402, in _make_request
    six.raise_from(e, None)
  File "<string>", line 2, in raise_from
  File "/Library/Frameworks/Python.framework/Versions/3.6/lib/python3.6/site-packages/telegram/vendor/ptb_urllib3/urllib3/connectionpool.py", line 398, in _make_request
    httplib_response = conn.getresponse()
  File "/Library/Frameworks/Python.framework/Versions/3.6/lib/python3.6/http/client.py", line 1331, in getresponse
    response.begin()
  File "/Library/Frameworks/Python.framework/Versions/3.6/lib/python3.6/http/client.py", line 297, in begin
    version, status, reason = self._read_status()
  File "/Library/Frameworks/Python.framework/Versions/3.6/lib/python3.6/http/client.py", line 258, in _read_status
    line = str(self.fp.readline(_MAXLINE + 1), "iso-8859-1")
  File "/Library/Frameworks/Python.framework/Versions/3.6/lib/python3.6/socket.py", line 586, in readinto
    return self._sock.recv_into(b)
  File "/Library/Frameworks/Python.framework/Versions/3.6/lib/python3.6/ssl.py", line 1009, in recv_into
    return self.read(nbytes, buffer)
  File "/Library/Frameworks/Python.framework/Versions/3.6/lib/python3.6/ssl.py", line 871, in read
    return self._sslobj.read(len, buffer)
  File "/Library/Frameworks/Python.framework/Versions/3.6/lib/python3.6/ssl.py", line 631, in read
    v = self._sslobj.read(len, buffer)
ConnectionResetError: [Errno 54] Connection reset by peer

During handling of the above exception, another exception occurred:

Traceback (most recent call last):
  File "/Library/Frameworks/Python.framework/Versions/3.6/lib/python3.6/site-packages/telegram/utils/request.py", line 195, in _request_wrapper
    resp = self._con_pool.request(*args, **kwargs)
  File "/Library/Frameworks/Python.framework/Versions/3.6/lib/python3.6/site-packages/telegram/vendor/ptb_urllib3/urllib3/request.py", line 70, in request
    **urlopen_kw)
  File "/Library/Frameworks/Python.framework/Versions/3.6/lib/python3.6/site-packages/telegram/vendor/ptb_urllib3/urllib3/request.py", line 148, in request_encode_body
    return self.urlopen(method, url, **extra_kw)
  File "/Library/Frameworks/Python.framework/Versions/3.6/lib/python3.6/site-packages/telegram/vendor/ptb_urllib3/urllib3/poolmanager.py", line 244, in urlopen
    response = conn.urlopen(method, u.request_uri, **kw)
  File "/Library/Frameworks/Python.framework/Versions/3.6/lib/python3.6/site-packages/telegram/vendor/ptb_urllib3/urllib3/connectionpool.py", line 666, in urlopen
    _stacktrace=sys.exc_info()[2])
  File "/Library/Frameworks/Python.framework/Versions/3.6/lib/python3.6/site-packages/telegram/vendor/ptb_urllib3/urllib3/util/retry.py", line 347, in increment
    raise six.reraise(type(error), error, _stacktrace)
  File "/Library/Frameworks/Python.framework/Versions/3.6/lib/python3.6/site-packages/telegram/vendor/ptb_urllib3/urllib3/packages/six.py", line 685, in reraise
    raise value.with_traceback(tb)
  File "/Library/Frameworks/Python.framework/Versions/3.6/lib/python3.6/site-packages/telegram/vendor/ptb_urllib3/urllib3/connectionpool.py", line 617, in urlopen
    chunked=chunked)
  File "/Library/Frameworks/Python.framework/Versions/3.6/lib/python3.6/site-packages/telegram/vendor/ptb_urllib3/urllib3/connectionpool.py", line 402, in _make_request
    six.raise_from(e, None)
  File "<string>", line 2, in raise_from
  File "/Library/Frameworks/Python.framework/Versions/3.6/lib/python3.6/site-packages/telegram/vendor/ptb_urllib3/urllib3/connectionpool.py", line 398, in _make_request
    httplib_response = conn.getresponse()
  File "/Library/Frameworks/Python.framework/Versions/3.6/lib/python3.6/http/client.py", line 1331, in getresponse
    response.begin()
  File "/Library/Frameworks/Python.framework/Versions/3.6/lib/python3.6/http/client.py", line 297, in begin
    version, status, reason = self._read_status()
  File "/Library/Frameworks/Python.framework/Versions/3.6/lib/python3.6/http/client.py", line 258, in _read_status
    line = str(self.fp.readline(_MAXLINE + 1), "iso-8859-1")
  File "/Library/Frameworks/Python.framework/Versions/3.6/lib/python3.6/socket.py", line 586, in readinto
    return self._sock.recv_into(b)
  File "/Library/Frameworks/Python.framework/Versions/3.6/lib/python3.6/ssl.py", line 1009, in recv_into
    return self.read(nbytes, buffer)
  File "/Library/Frameworks/Python.framework/Versions/3.6/lib/python3.6/ssl.py", line 871, in read
    return self._sslobj.read(len, buffer)
  File "/Library/Frameworks/Python.framework/Versions/3.6/lib/python3.6/ssl.py", line 631, in read
    v = self._sslobj.read(len, buffer)
telegram.vendor.ptb_urllib3.urllib3.exceptions.ProtocolError: ('Connection aborted.', ConnectionResetError(54, 'Connection reset by peer'))

During handling of the above exception, another exception occurred:

Traceback (most recent call last):
  File "/Library/Frameworks/Python.framework/Versions/3.6/lib/python3.6/site-packages/telegram/ext/dispatcher.py", line 279, in process_update
    handler.handle_update(update, self)
  File "/Library/Frameworks/Python.framework/Versions/3.6/lib/python3.6/site-packages/telegram/ext/messagehandler.py", line 169, in handle_update
    return self.callback(dispatcher.bot, update, **optional_args)
  File "bot1.py", line 32, in talk_to_me
    update.message.reply_text(':********')
  File "/Library/Frameworks/Python.framework/Versions/3.6/lib/python3.6/site-packages/telegram/message.py", line 432, in reply_text
    return self.bot.send_message(self.chat_id, *args, **kwargs)
  File "/Library/Frameworks/Python.framework/Versions/3.6/lib/python3.6/site-packages/telegram/bot.py", line 60, in decorator
    result = func(self, *args, **kwargs)
  File "/Library/Frameworks/Python.framework/Versions/3.6/lib/python3.6/site-packages/telegram/bot.py", line 85, in decorator
    result = self._request.post(url, data, timeout=kwargs.get('timeout'))
  File "/Library/Frameworks/Python.framework/Versions/3.6/lib/python3.6/site-packages/telegram/utils/request.py", line 278, in post
    **urlopen_kwargs)
  File "/Library/Frameworks/Python.framework/Versions/3.6/lib/python3.6/site-packages/telegram/utils/request.py", line 201, in _request_wrapper
    raise NetworkError('urllib3 HTTPError {0}'.format(error))
telegram.error.NetworkError: urllib3 HTTPError ('Connection aborted.', ConnectionResetError(54, 'Connection reset by peer'))
telegram.ext.updater - INFO - Received signal 2 (SIGINT), stopping...
telegram.ext.updater - INFO - Received signal 2 (SIGINT), stopping...
telegram.ext.updater - WARNING - Exiting immediately!
